<mujoco model="ur5e_door">
  <include file="./env_ur5e_common.xml"/>

  <include file="../../robots/ur5e/ur5e_integrated_config.xml"/>

  <asset>
    <texture name="table_plate2" file="table/table2.png" type="2d"/>
    <material name="table_plate2" texture="table_plate2" specular="0.0" shininess="0.0"/>
  </asset>

  <worldbody>
    <light pos="0 0 1.5" dir="0 0 -1" directional="true" diffuse="0.5 0.5 0.5" castshadow="false"/>

    <camera name="front" mode="fixed" pos="0.5 0.0 1.5" euler="0.0 0.785398 1.5708"/>
    <camera name="side" mode="fixed" pos="-0.1 -0.75 0.9" euler="1.5708 0.0 0.0"/>

    <geom name="floor" size="0 0 0.05" type="plane" material="floor"/>

    <body name="table">
      <geom type="box" size="0.275 0.5 0.4" pos="0 0 0.4" material="table_base"/>
      <geom type="box" size="0.275 0.5 0.0075" pos="0 0 0.8075" material="table_plate2"/>
    </body>

    <body name="stand">
      <geom type="box" size="0.33 0.33 0.4" pos="-0.605 0 0.4" material="stand"/>
    </body>

    <body name="ur5e_root_frame" pos="-0.605 0.0 0.8">
      <include file="../../robots/ur5e/ur5e_integrated_body.xml"/>
    </body>

    <body name="door" pos="0.15 -0.08 0.815">
      <geom type="cylinder" size="0.015 0.15" pos="0.0 0.1 0.15" rgba="0.1 0.3 0.1 1.0"/>
      <geom type="cylinder" size="0.015 0.15" pos="0.0 -0.1 0.15" rgba="0.1 0.3 0.1 1.0"/>
      <body pos="0.0 0.1 0.15">
        <joint name="door" axis="0 0 1" range="-3.1415 0.0" armature="1e-5"/>
        <geom type="box" size="0.005 0.09 0.145" pos="0.0 -0.1 0.0" rgba="0.7 0.9 0.9 1.0"/>
        <geom type="cylinder" size="0.005 0.02" pos="-0.02 -0.17 0.0" euler="0.0 1.5708 0.0" rgba="0.1 0.6 0.3 1.0"/>
        <geom type="cylinder" size="0.0075 0.03" pos="-0.035 -0.145 0.0" euler="1.5708 0.0 0.0" rgba="0.1 0.6 0.3 1.0"/>
      </body>
    </body>
  </worldbody>
</mujoco>
