<mujoco model="ur5e_cabinet">
  <include file="./env_ur5e_common.xml"/>

  <include file="../../robots/ur5e/ur5e_integrated_config.xml"/>

  <asset>
    <texture name="table_plate2" file="table/table2.png" type="2d"/>
    <material name="table_plate2" texture="table_plate2" specular="0.0" shininess="0.0"/>
  </asset>

  <worldbody>
    <light pos="0 0 1.5" dir="0 0 -1" directional="true" diffuse="0.5 0.5 0.5" castshadow="false"/>

    <camera name="front" mode="fixed" pos="0.5 0.0 1.5" euler="0.0 0.785398 1.5708"/>
    <camera name="side" mode="fixed" pos="-0.1 -0.75 0.9" euler="1.5708 0.0 0.0"/>

    <geom name="floor" size="0 0 0.05" type="plane" material="floor"/>

    <body name="table">
      <geom type="box" size="0.275 0.5 0.4" pos="0 0 0.4" material="table_base"/>
      <geom type="box" size="0.275 0.5 0.0075" pos="0 0 0.8075" material="table_plate2"/>
    </body>

    <body name="stand">
      <geom type="box" size="0.33 0.33 0.4" pos="-0.605 0 0.4" material="stand"/>
    </body>

    <body name="ur5e_root_frame" pos="-0.605 0.0 0.8">
      <include file="../../robots/ur5e/ur5e_integrated_body.xml"/>
    </body>

    <body name="cabinet" pos="0.12 -0.05 0.815">
      <body pos="0.0 0.0 0.0">
        <geom type="box" size="0.1 0.1 0.005" pos="0.0 0.0 0.005" rgba="0.1 0.5 0.1 1.0"/>
        <geom type="box" size="0.1 0.005 0.04" pos="0.0 0.105 0.04" rgba="0.1 0.5 0.1 1.0"/>
        <geom type="box" size="0.1 0.005 0.04" pos="0.0 -0.105 0.04" rgba="0.1 0.5 0.1 1.0"/>
        <geom type="box" size="0.005 0.1 0.04" pos="0.095 0.0 0.04" rgba="0.1 0.5 0.1 1.0"/>
        <geom type="box" size="0.005 0.05 0.035" pos="-0.085 0.05 0.045" rgba="0.9 0.6 0.1 1.0"/>
        <body pos="-0.095 0.0 0.0">
          <joint name="slide" type="slide" axis="0 1 0" range="0.0 0.1" armature="1e-5"/>
          <geom type="box" size="0.005 0.05 0.035" pos="0.0 -0.05 0.045" rgba="0.9 0.3 0.7 1.0"/>
          <geom type="box" size="0.01 0.002 0.018" pos="-0.01 -0.095 0.045" rgba="0.6 0.0 0.4 1.0"/>
        </body>
      </body>
      <body pos="0.0 0.0 0.08">
        <geom type="box" size="0.095 0.1 0.005" pos="0.0 0.0 0.005" rgba="0.3 0.3 0.3 1.0"/>
        <geom type="box" size="0.1 0.005 0.04" pos="0.0 0.105 0.04" rgba="0.1 0.5 0.1 1.0"/>
        <geom type="box" size="0.1 0.005 0.04" pos="0.0 -0.105 0.04" rgba="0.1 0.5 0.1 1.0"/>
        <geom type="box" size="0.005 0.1 0.04" pos="0.095 0.0 0.04" rgba="0.1 0.5 0.1 1.0"/>
        <geom type="box" size="0.005 0.1 0.025" pos="-0.095 0.0 0.025" rgba="0.1 0.8 0.8 1.0"/>
        <body pos="0.095 0.0 0.08">
          <joint name="hinge" axis="0 1 0" range="0.0 3.1415" armature="1e-5"/>
          <geom type="box" size="0.1 0.11 0.005" pos="-0.095 0.0 0.005" rgba="0.8 0.8 0.1 1.0"/>
        </body>
      </body>
    </body>
  </worldbody>
</mujoco>
