<?xml version="1.0" ?>
<robot name="cabinet">
  <link name="base_link"/>
  <link name="door">
    <visual>
      <origin xyz="0.0 -0.1 0.0"/>
      <geometry>
        <box size="0.15 0.2 0.01"/>
      </geometry>
      <material name="light_green">
        <color rgba="0.1 0.8 0.1 1.0"/>
      </material>
    </visual>
    <collision>
      <origin xyz="0.0 -0.1 0.0"/>
      <geometry>
        <box size="0.15 0.2 0.01"/>
      </geometry>
    </collision>
    <inertial>
      <mass value="0.1"/>
      <inertia ixx="0.01" ixy="0.0" ixz="0.0" iyy="0.01" iyz="0.0" izz="0.01"/>
    </inertial>
  </link>
  <link name="bottom">
    <visual>
      <geometry>
        <box size="0.15 0.2 0.01"/>
      </geometry>
      <material name="light_brown">
        <color rgba="0.65 0.50 0.18 1.0"/>
      </material>
    </visual>
    <collision>
      <geometry>
        <box size="0.15 0.2 0.01"/>
      </geometry>
    </collision>
    <inertial>
      <mass value="0.1"/>
      <inertia ixx="0.01" ixy="0.0" ixz="0.0" iyy="0.01" iyz="0.0" izz="0.01"/>
    </inertial>
  </link>
  <link name="wall1">
    <visual>
      <geometry>
        <box size="0.13 0.01 0.25"/>
      </geometry>
      <material name="pink">
        <color rgba="0.8 0.1 0.5 1.0"/>
      </material>
    </visual>
    <collision>
      <geometry>
        <box size="0.13 0.01 0.25"/>
      </geometry>
    </collision>
    <inertial>
      <mass value="0.1"/>
      <inertia ixx="0.01" ixy="0.0" ixz="0.0" iyy="0.01" iyz="0.0" izz="0.01"/>
    </inertial>
  </link>
  <link name="wall2">
    <visual>
      <geometry>
        <box size="0.15 0.01 0.3"/>
      </geometry>
      <material name="light_brown">
        <color rgba="0.65 0.50 0.18 1.0"/>
      </material>
    </visual>
    <collision>
      <geometry>
        <box size="0.15 0.01 0.3"/>
      </geometry>
    </collision>
    <inertial>
      <mass value="0.1"/>
      <inertia ixx="0.01" ixy="0.0" ixz="0.0" iyy="0.01" iyz="0.0" izz="0.01"/>
    </inertial>
  </link>
  <link name="wall3">
    <visual>
      <geometry>
        <box size="0.01 0.2 0.3"/>
      </geometry>
      <material name="light_brown">
        <color rgba="0.65 0.50 0.18 1.0"/>
      </material>
    </visual>
    <collision>
      <geometry>
        <box size="0.01 0.2 0.3"/>
      </geometry>
    </collision>
    <inertial>
      <mass value="0.1"/>
      <inertia ixx="0.01" ixy="0.0" ixz="0.0" iyy="0.01" iyz="0.0" izz="0.01"/>
    </inertial>
  </link>
  <link name="wall4">
    <visual>
      <geometry>
        <box size="0.01 0.2 0.3"/>
      </geometry>
      <material name="light_brown">
        <color rgba="0.65 0.50 0.18 1.0"/>
      </material>
    </visual>
    <collision>
      <geometry>
        <box size="0.01 0.2 0.3"/>
      </geometry>
    </collision>
    <inertial>
      <mass value="0.1"/>
      <inertia ixx="0.01" ixy="0.0" ixz="0.0" iyy="0.01" iyz="0.0" izz="0.01"/>
    </inertial>
  </link>
  <joint name="door" type="revolute">
    <origin xyz="0.0 0.101 0.306"/>
    <axis xyz="1 0 0"/>
    <limit lower="-6.28" upper="0.0" effort="1.0" velocity="1.0"/>
    <parent link="base_link"/>
    <child link="door"/>
  </joint>
  <joint name="bottom" type="fixed">
    <origin xyz="0.0 0.0 0.0"/>
    <parent link="base_link"/>
    <child link="bottom"/>
  </joint>
  <joint name="wall1" type="fixed">
    <origin xyz="0.0 -0.095 0.125"/>
    <parent link="base_link"/>
    <child link="wall1"/>
  </joint>
  <joint name="wall2" type="fixed">
    <origin xyz="0.0 0.095 0.15"/>
    <parent link="base_link"/>
    <child link="wall2"/>
  </joint>
  <joint name="wall3" type="fixed">
    <origin xyz="-0.07 0.0 0.15"/>
    <parent link="base_link"/>
    <child link="wall3"/>
  </joint>
  <joint name="wall4" type="fixed">
    <origin xyz="0.07 0.0 0.15"/>
    <parent link="base_link"/>
    <child link="wall4"/>
  </joint>
</robot>
