<?xml version="1.0" ?>
<!--
    This URDF model was generated by converting the MuJoCo model using the tool [1].
    [1] https://pypi.org/project/mjcf-urdf-simple-converter/
-->
<robot name="converted_robot">
   <link name="world">
      <inertial>
         <origin xyz="0.0 0.0 0.0" rpy="0.0 0.0 0.0"/>
         <mass value="0.0"/>
         <inertia ixx="0.0" iyy="0.0" izz="0.0" ixy="0" ixz="0" iyz="0"/>
      </inertial>
   </link>
   <link name="base_link">
      <inertial>
         <origin xyz="-0.025978 -0.005498 0.17633" rpy="0.07658944484691692 -0.14074197991458326 0.08424682781595873"/>
         <mass value="50.0"/>
         <inertia ixx="0.378627" iyy="0.344913" izz="0.145159" ixy="0" ixz="0" iyz="0"/>
      </inertial>
      <visual name="base">
         <origin xyz="-0.03641712720598756 0.00045202167811737485 0.263125050393483" rpy="-0.0018958241508676304 -0.22047792419913836 0.0009596578307862437"/>
         <geometry>
            <mesh filename="file://converted_base.stl"/>
         </geometry>
         <material name="white"/>
      </visual>
   </link>
   <joint type="fixed" name="world2base_link_fixed">
      <parent link="world"/>
      <child link="base_link"/>
      <origin xyz="0.0 0.0 0.0" rpy="0.0 0.0 0.0"/>
   </joint>
   <link name="base_range_sensor_link">
      <inertial>
         <origin xyz="0.0 0.0 0.0" rpy="0.0 0.0 0.0"/>
         <mass value="0.01"/>
         <inertia ixx="0.001" iyy="0.001" izz="0.001" ixy="0" ixz="0" iyz="0"/>
      </inertial>
      <visual name="laser">
         <origin xyz="2.9961710733188483e-10 -1.4073088328788368e-10 0.006362492251619581" rpy="0.0 0.0 0.0"/>
         <geometry>
            <mesh filename="file://converted_laser.stl"/>
         </geometry>
         <material name="white"/>
      </visual>
   </link>
   <joint type="fixed" name="base_link2base_range_sensor_link_fixed">
      <parent link="base_link"/>
      <child link="base_range_sensor_link"/>
      <origin xyz="0.1675 0.0 0.1844" rpy="0.0 0.0 0.0"/>
   </joint>
   <link name="base_imu_frame">
      <inertial>
         <origin xyz="0.0 0.0 0.0" rpy="0.0 0.0 0.0"/>
         <mass value="0.01"/>
         <inertia ixx="0.001" iyy="0.001" izz="0.001" ixy="0" ixz="0" iyz="0"/>
      </inertial>
   </link>
   <joint type="fixed" name="base_link2base_imu_frame_fixed">
      <parent link="base_link"/>
      <child link="base_imu_frame"/>
      <origin xyz="0.0005 0.1296 0.181" rpy="0.0 0.0 0.0"/>
   </joint>
   <link name="base_f_bumper_link">
      <inertial>
         <origin xyz="0.0 0.0 0.0" rpy="1.5707963267948966 -1.5707963267948966 0.0"/>
         <mass value="0.06"/>
         <inertia ixx="0.001875" iyy="0.001437" izz="0.001437" ixy="0" ixz="0" iyz="0"/>
      </inertial>
      <visual name="bumper">
         <origin xyz="0.12368861145497913 0.0006512333388533162 0.02924589803813435" rpy="1.5707963267948966 -1.5707963267948966 0.0"/>
         <geometry>
            <mesh filename="file://converted_bumper.stl"/>
         </geometry>
         <material name="white"/>
      </visual>
   </link>
   <joint type="fixed" name="base_link2base_f_bumper_link_fixed">
      <parent link="base_link"/>
      <child link="base_f_bumper_link"/>
      <origin xyz="0.0 0.0 0.0" rpy="0.0 0.0 0.0"/>
   </joint>
   <link name="base_b_bumper_link">
      <inertial>
         <origin xyz="0.0 0.0 0.0" rpy="1.5707963267948966 -1.5707963267948966 0.0"/>
         <mass value="0.06"/>
         <inertia ixx="0.001875" iyy="0.001437" izz="0.001437" ixy="0" ixz="0" iyz="0"/>
      </inertial>
      <visual name="bumper">
         <origin xyz="0.12368861145497913 0.0006512333388533162 0.02924589803813435" rpy="1.5707963267948966 -1.5707963267948966 0.0"/>
         <geometry>
            <mesh filename="file://converted_bumper.stl"/>
         </geometry>
         <material name="white"/>
      </visual>
   </link>
   <joint type="fixed" name="base_link2base_b_bumper_link_fixed">
      <parent link="base_link"/>
      <child link="base_b_bumper_link"/>
      <origin xyz="0.0 0.0013 0.0" rpy="0.0 0.0 3.141592653589793"/>
   </joint>
   <link name="torso_lift_link">
      <inertial>
         <origin xyz="-0.051142 0.003454 -0.2905" rpy="-0.01632718038041414 -0.027406021497923705 2.06861111007671"/>
         <mass value="3.42078"/>
         <inertia ixx="0.105342" iyy="0.104252" izz="0.0127461" ixy="0" ixz="0" iyz="0"/>
      </inertial>
      <visual name="torso">
         <origin xyz="-0.03774660569490806 -0.00035597916658452957 -0.2898779702706376" rpy="0.00012490530025177637 0.0009055500383232662 1.570382022801644"/>
         <geometry>
            <mesh filename="file://converted_torso.stl"/>
         </geometry>
         <material name="white"/>
      </visual>
   </link>
   <link name="torso_lift_joint_jointbody">
      <inertial>
         <origin xyz="0.0 0.0 0.0" rpy="0.0 0.0 0.0"/>
         <mass value="0.001"/>
         <inertia ixx="1e-09" iyy="1e-09" izz="1e-09" ixy="0" ixz="0" iyz="0"/>
      </inertial>
   </link>
   <!-- TODO: Disable torso_lift_joint because mimic joint is not supported in the pinocchio library. This will be resolved when you can install pinocchio version 3.5.0 with pip. -->
   <joint type="fixed" name="torso_lift_joint">
      <!-- <mimic joint="arm_lift_joint" multiplier="0.5"/> -->
      <axis xyz="0.0 0.0 1.0"/>
      <limit lower="0.0" upper="0.345" effort="100" velocity="100"/>
      <parent link="base_link"/>
      <child link="torso_lift_joint_jointbody"/>
      <origin xyz="0.0 0.0 0.752" rpy="0.0 0.0 0.0"/>
   </joint>
   <joint type="fixed" name="torso_lift_joint_offset">
      <parent link="torso_lift_joint_jointbody"/>
      <child link="torso_lift_link"/>
      <origin xyz="-0.0 -0.0 -0.0" rpy="0.0 0.0 0.0"/>
   </joint>
   <link name="head_pan_link">
      <inertial>
         <origin xyz="0.001724 -0.001969 -0.028886" rpy="0.9941665639085965 0.3930704336385935 0.08892982332385102"/>
         <mass value="0.571903"/>
         <inertia ixx="0.00102408" iyy="0.00077623" izz="0.000589392" ixy="0" ixz="0" iyz="0"/>
      </inertial>
      <visual name="head_pan">
         <origin xyz="0.0022138940878817562 -3.131935760808483e-05 -0.01963035607837507" rpy="-1.5716262159313081 -1.0128298473122188 -3.139735060773426"/>
         <geometry>
            <mesh filename="file://converted_head_pan.stl"/>
         </geometry>
         <material name="white"/>
      </visual>
   </link>
   <joint type="fixed" name="torso_lift_link2head_pan_link_fixed">
      <parent link="torso_lift_link"/>
      <child link="head_pan_link"/>
      <origin xyz="0.0 0.0 0.0" rpy="0.0 0.0 0.0"/>
   </joint>
   <link name="head_tilt_link">
      <inertial>
         <origin xyz="-0.055376 -0.002436 0.117733" rpy="0.03015133003478542 -0.4575695247763243 -0.013744861029680018"/>
         <mass value="2.1238"/>
         <inertia ixx="0.0218915" iyy="0.0149823" izz="0.0091862" ixy="0" ixz="0" iyz="0"/>
      </inertial>
      <visual name="head">
         <origin xyz="-0.05543836818856249 3.4786069897089997e-05 0.09133437667110178" rpy="0.015753447533037444 -0.6017962892414235 -0.008135922889519346"/>
         <geometry>
            <mesh filename="file://converted_head.stl"/>
         </geometry>
         <material name="white"/>
      </visual>
      <visual name="tablet">
         <origin xyz="-0.07527558516613439 -0.0003932226940284872 0.14603397133196497" rpy="1.5767015175762835 -0.2611512069931443 -0.0002549960482848279"/>
         <geometry>
            <mesh filename="file://converted_tablet.stl"/>
         </geometry>
         <material name="white"/>
      </visual>
   </link>
   <joint type="fixed" name="head_pan_link2head_tilt_link_fixed">
      <parent link="head_pan_link"/>
      <child link="head_tilt_link"/>
      <origin xyz="0.02 0.0 0.0" rpy="0.0 0.0 0.0"/>
   </joint>
   <link name="head_l_stereo_camera_link">
      <inertial>
         <origin xyz="0.0 0.0 0.0" rpy="0.0 0.0 0.0"/>
         <mass value="0.01"/>
         <inertia ixx="0.001" iyy="0.001" izz="0.001" ixy="0" ixz="0" iyz="0"/>
      </inertial>
   </link>
   <joint type="fixed" name="head_tilt_link2head_l_stereo_camera_link_fixed">
      <parent link="head_tilt_link"/>
      <child link="head_l_stereo_camera_link"/>
      <origin xyz="0.02 0.07 0.061" rpy="-1.5707963267948966 0.0 -1.5707963267948966"/>
   </joint>
   <link name="head_l_stereo_camera_gazebo_frame">
      <inertial>
         <origin xyz="0.0 0.0 0.0" rpy="0.0 0.0 0.0"/>
         <mass value="0.01"/>
         <inertia ixx="0.001" iyy="0.001" izz="0.001" ixy="0" ixz="0" iyz="0"/>
      </inertial>
   </link>
   <joint type="fixed" name="head_l_stereo_camera_link2head_l_stereo_camera_gazebo_frame_fixed">
      <parent link="head_l_stereo_camera_link"/>
      <child link="head_l_stereo_camera_gazebo_frame"/>
      <origin xyz="0.0 0.0 0.0" rpy="1.5707963267948966 -1.5707963267948966 0.0"/>
   </joint>
   <link name="head_r_stereo_camera_link">
      <inertial>
         <origin xyz="0.0 0.0 0.0" rpy="0.0 0.0 0.0"/>
         <mass value="0.01"/>
         <inertia ixx="0.001" iyy="0.001" izz="0.001" ixy="0" ixz="0" iyz="0"/>
      </inertial>
   </link>
   <joint type="fixed" name="head_tilt_link2head_r_stereo_camera_link_fixed">
      <parent link="head_tilt_link"/>
      <child link="head_r_stereo_camera_link"/>
      <origin xyz="0.02 -0.07 0.061" rpy="-1.5707963267948966 0.0 -1.5707963267948966"/>
   </joint>
   <link name="head_r_stereo_camera_gazebo_frame">
      <inertial>
         <origin xyz="0.0 0.0 0.0" rpy="0.0 0.0 0.0"/>
         <mass value="0.01"/>
         <inertia ixx="0.001" iyy="0.001" izz="0.001" ixy="0" ixz="0" iyz="0"/>
      </inertial>
   </link>
   <joint type="fixed" name="head_r_stereo_camera_link2head_r_stereo_camera_gazebo_frame_fixed">
      <parent link="head_r_stereo_camera_link"/>
      <child link="head_r_stereo_camera_gazebo_frame"/>
      <origin xyz="0.0 0.0 0.0" rpy="1.5707963267948966 -1.5707963267948966 0.0"/>
   </joint>
   <link name="head_center_camera_frame">
      <inertial>
         <origin xyz="0.0 0.0 0.0" rpy="0.0 0.0 0.0"/>
         <mass value="0.01"/>
         <inertia ixx="0.001" iyy="0.001" izz="0.001" ixy="0" ixz="0" iyz="0"/>
      </inertial>
   </link>
   <joint type="fixed" name="head_tilt_link2head_center_camera_frame_fixed">
      <parent link="head_tilt_link"/>
      <child link="head_center_camera_frame"/>
      <origin xyz="0.0195 0.0 0.061" rpy="-1.5707963267948966 0.0 -1.5707963267948966"/>
   </joint>
   <link name="head_center_camera_gazebo_frame">
      <inertial>
         <origin xyz="0.0 0.0 0.0" rpy="0.0 0.0 0.0"/>
         <mass value="0.01"/>
         <inertia ixx="0.001" iyy="0.001" izz="0.001" ixy="0" ixz="0" iyz="0"/>
      </inertial>
   </link>
   <joint type="fixed" name="head_center_camera_frame2head_center_camera_gazebo_frame_fixed">
      <parent link="head_center_camera_frame"/>
      <child link="head_center_camera_gazebo_frame"/>
      <origin xyz="0.0 0.0 0.0" rpy="1.5707963267948966 -1.5707963267948966 0.0"/>
   </joint>
   <link name="head_rgbd_sensor_link">
      <inertial>
         <origin xyz="0.0 0.0 0.0" rpy="0.0 0.0 0.0"/>
         <mass value="0.01"/>
         <inertia ixx="0.001" iyy="0.001" izz="0.001" ixy="0" ixz="0" iyz="0"/>
      </inertial>
      <visual name="xtion">
         <origin xyz="0.022312525947092918 0.003084133188058455 -0.015074222592352995" rpy="1.5709012417133033 -0.03854424120292732 1.5702168240352687"/>
         <geometry>
            <mesh filename="file://converted_xtion.stl"/>
         </geometry>
         <material name="white"/>
      </visual>
   </link>
   <joint type="fixed" name="head_tilt_link2head_rgbd_sensor_link_fixed">
      <parent link="head_tilt_link"/>
      <child link="head_rgbd_sensor_link"/>
      <origin xyz="-0.079796 0.022 0.215172" rpy="-1.5707963267948966 0.0 -1.5707963267948966"/>
   </joint>
   <link name="head_rgbd_sensor_gazebo_frame">
      <inertial>
         <origin xyz="0.0 0.0 0.0" rpy="0.0 0.0 0.0"/>
         <mass value="0.01"/>
         <inertia ixx="0.001" iyy="0.001" izz="0.001" ixy="0" ixz="0" iyz="0"/>
      </inertial>
   </link>
   <joint type="fixed" name="head_rgbd_sensor_link2head_rgbd_sensor_gazebo_frame_fixed">
      <parent link="head_rgbd_sensor_link"/>
      <child link="head_rgbd_sensor_gazebo_frame"/>
      <origin xyz="0.0 0.0 0.0" rpy="1.5707963267948966 -1.5707963267948966 0.0"/>
   </joint>
   <link name="arm_lift_link">
      <inertial>
         <origin xyz="0.051549 0.042438 -0.064145" rpy="-0.5605067167891848 -0.9721593721508488 -2.57955559744971"/>
         <mass value="1.27582"/>
         <inertia ixx="0.00909548" iyy="0.00799354" izz="0.00328099" ixy="0" ixz="0" iyz="0"/>
      </inertial>
      <visual name="shoulder">
         <origin xyz="0.08607395171499123 0.03730696555091683 -0.04823706647974966" rpy="1.905587425145462 0.22398533336610238 -0.13339125688733944"/>
         <geometry>
            <mesh filename="file://converted_shoulder.stl"/>
         </geometry>
         <material name="white"/>
      </visual>
   </link>
   <link name="arm_lift_joint_jointbody">
      <inertial>
         <origin xyz="0.0 0.0 0.0" rpy="0.0 0.0 0.0"/>
         <mass value="0.001"/>
         <inertia ixx="1e-09" iyy="1e-09" izz="1e-09" ixy="0" ixz="0" iyz="0"/>
      </inertial>
   </link>
   <joint type="prismatic" name="arm_lift_joint">
      <axis xyz="0.0 0.0 1.0"/>
      <limit lower="0.0" upper="0.69" effort="100" velocity="100"/>
      <parent link="base_link"/>
      <child link="arm_lift_joint_jointbody"/>
      <origin xyz="0.0 0.0 0.34" rpy="0.0 0.0 0.0"/>
   </joint>
   <joint type="fixed" name="arm_lift_joint_offset">
      <parent link="arm_lift_joint_jointbody"/>
      <child link="arm_lift_link"/>
      <origin xyz="-0.0 -0.0 -0.0" rpy="0.0 0.0 0.0"/>
   </joint>
   <link name="arm_flex_link">
      <inertial>
         <origin xyz="0.000632 0.006404 0.118529" rpy="-0.01671172463917324 0.0031171778413268125 -0.046796821111315556"/>
         <mass value="1.33929"/>
         <inertia ixx="0.00752902" iyy="0.00710259" izz="0.00155039" ixy="0" ixz="0" iyz="0"/>
      </inertial>
      <visual name="arm_flex">
         <origin xyz="-0.00045899058288166714 0.006583411837262373 0.1060690102634234" rpy="-0.014385170116359338 -0.005292849378514264 -0.006022959567068342"/>
         <geometry>
            <mesh filename="file://converted_arm_flex.stl"/>
         </geometry>
         <material name="white"/>
      </visual>
   </link>
   <link name="arm_flex_joint_jointbody">
      <inertial>
         <origin xyz="0.0 0.0 0.0" rpy="0.0 0.0 0.0"/>
         <mass value="0.001"/>
         <inertia ixx="1e-09" iyy="1e-09" izz="1e-09" ixy="0" ixz="0" iyz="0"/>
      </inertial>
   </link>
   <joint type="revolute" name="arm_flex_joint">
      <parent link="arm_lift_link"/>
      <child link="arm_flex_joint_jointbody"/>
      <origin xyz="0.141 0.078 0.0" rpy="0.0 0.0 0.0"/>
      <axis xyz="0.0 -1.0 0.0"/>
      <limit lower="-2.62" upper="0.0" effort="100" velocity="100"/>
   </joint>
   <joint type="fixed" name="arm_flex_joint_offset">
      <parent link="arm_flex_joint_jointbody"/>
      <child link="arm_flex_link"/>
      <origin xyz="-0.0 -0.0 -0.0" rpy="0.0 0.0 0.0"/>
   </joint>
   <link name="arm_roll_link">
      <inertial>
         <origin xyz="-0.006927 0.002039 -0.064837" rpy="1.5749673965413329 -0.12042108009183838 -0.005735259548901972"/>
         <mass value="0.247936"/>
         <inertia ixx="0.00426928" iyy="0.00411787" izz="0.00078077" ixy="0" ixz="0" iyz="0"/>
      </inertial>
      <visual name="arm_roll">
         <origin xyz="-0.004909095971536465 0.003416739255037993 -0.047203090879916386" rpy="0.1344676818217645 0.058588981154007014 -0.00592650872136212"/>
         <geometry>
            <mesh filename="file://converted_arm_roll.stl"/>
         </geometry>
         <material name="white"/>
      </visual>
   </link>
   <link name="arm_roll_joint_jointbody">
      <inertial>
         <origin xyz="0.0 0.0 0.0" rpy="0.0 0.0 0.0"/>
         <mass value="0.001"/>
         <inertia ixx="1e-09" iyy="1e-09" izz="1e-09" ixy="0" ixz="0" iyz="0"/>
      </inertial>
   </link>
   <joint type="revolute" name="arm_roll_joint">
      <parent link="arm_flex_link"/>
      <child link="arm_roll_joint_jointbody"/>
      <origin xyz="0.005 0.0 0.345" rpy="0.0 0.0 0.0"/>
      <axis xyz="0.0 0.0 1.0"/>
      <limit lower="-2.09" upper="3.84" effort="100" velocity="100"/>
   </joint>
   <joint type="fixed" name="arm_roll_joint_offset">
      <parent link="arm_roll_joint_jointbody"/>
      <child link="arm_roll_link"/>
      <origin xyz="-0.0 -0.0 -0.0" rpy="0.0 0.0 0.0"/>
   </joint>
   <link name="wrist_flex_link">
      <inertial>
         <origin xyz="0.000131 -0.003929 0.00217" rpy="1.6669404025225198 0.0012887265193397557 0.013855073199448897"/>
         <mass value="0.681225"/>
         <inertia ixx="7.43604e-05" iyy="6.49274e-05" izz="3.81796e-05" ixy="0" ixz="0" iyz="0"/>
      </inertial>
   </link>
   <link name="wrist_flex_joint_jointbody">
      <inertial>
         <origin xyz="0.0 0.0 0.0" rpy="0.0 0.0 0.0"/>
         <mass value="0.001"/>
         <inertia ixx="1e-09" iyy="1e-09" izz="1e-09" ixy="0" ixz="0" iyz="0"/>
      </inertial>
   </link>
   <joint type="revolute" name="wrist_flex_joint">
      <parent link="arm_roll_link"/>
      <child link="wrist_flex_joint_jointbody"/>
      <origin xyz="0.0 0.0 0.0" rpy="0.0 0.0 0.0"/>
      <axis xyz="0.0 -1.0 0.0"/>
      <limit lower="-1.92" upper="1.22" effort="100" velocity="100"/>
   </joint>
   <joint type="fixed" name="wrist_flex_joint_offset">
      <parent link="wrist_flex_joint_jointbody"/>
      <child link="wrist_flex_link"/>
      <origin xyz="-0.0 -0.0 -0.0" rpy="0.0 0.0 0.0"/>
   </joint>
   <link name="wrist_ft_sensor_mount_link">
      <inertial>
         <origin xyz="0.0 0.0 0.0" rpy="0.0 0.0 0.0"/>
         <mass value="0.01"/>
         <inertia ixx="0.001" iyy="0.001" izz="0.001" ixy="0" ixz="0" iyz="0"/>
      </inertial>
   </link>
   <link name="wrist_roll_joint_jointbody">
      <inertial>
         <origin xyz="0.0 0.0 0.0" rpy="0.0 0.0 0.0"/>
         <mass value="0.001"/>
         <inertia ixx="1e-09" iyy="1e-09" izz="1e-09" ixy="0" ixz="0" iyz="0"/>
      </inertial>
   </link>
   <joint type="revolute" name="wrist_roll_joint">
      <parent link="wrist_flex_link"/>
      <child link="wrist_roll_joint_jointbody"/>
      <origin xyz="0.0 0.0 0.0" rpy="0.0 0.0 0.0"/>
      <axis xyz="0.0 0.0 1.0"/>
      <limit lower="-1.92" upper="3.67" effort="100" velocity="100"/>
   </joint>
   <joint type="fixed" name="wrist_roll_joint_offset">
      <parent link="wrist_roll_joint_jointbody"/>
      <child link="wrist_ft_sensor_mount_link"/>
      <origin xyz="-0.0 -0.0 -0.0" rpy="0.0 0.0 0.0"/>
   </joint>
   <link name="wrist_ft_sensor_frame">
      <inertial>
         <origin xyz="0.0 0.0 0.0" rpy="0.0 0.0 0.0"/>
         <mass value="0.01"/>
         <inertia ixx="0.001" iyy="0.001" izz="0.001" ixy="0" ixz="0" iyz="0"/>
      </inertial>
   </link>
   <joint type="fixed" name="wrist_ft_sensor_mount_link2wrist_ft_sensor_frame_fixed">
      <parent link="wrist_ft_sensor_mount_link"/>
      <child link="wrist_ft_sensor_frame"/>
      <origin xyz="0.0 0.0 0.0735" rpy="3.141592653589793 0.0 0.0"/>
   </joint>
   <link name="wrist_roll_link">
      <inertial>
         <origin xyz="-0.001416 -0.001547 0.081689" rpy="0.09427208758049119 -0.05730930495604891 -0.2917166502479991"/>
         <mass value="0.761692"/>
         <inertia ixx="0.000811657" iyy="0.000766039" izz="0.000449422" ixy="0" ixz="0" iyz="0"/>
      </inertial>
      <visual name="wrist_roll">
         <origin xyz="-0.007677131478003973 -1.5261556648812353e-05 0.09334523618390513" rpy="1.5778247223776705 -0.4169056567753775 0.0012930681869987026"/>
         <geometry>
            <mesh filename="file://converted_wrist_roll.stl"/>
         </geometry>
         <material name="white"/>
      </visual>
   </link>
   <joint type="fixed" name="wrist_ft_sensor_frame2wrist_roll_link_fixed">
      <parent link="wrist_ft_sensor_frame"/>
      <child link="wrist_roll_link"/>
      <origin xyz="0.0 0.0 0.0735" rpy="3.141592653589793 0.0 0.0"/>
   </joint>
   <link name="hand_palm_link">
      <inertial>
         <origin xyz="0.0 0.0 0.0" rpy="0.0 0.0 0.0"/>
         <mass value="0.15"/>
         <inertia ixx="0.015" iyy="0.015" izz="0.015" ixy="0" ixz="0" iyz="0"/>
      </inertial>
      <visual name="palm">
         <origin xyz="0.001287775579688129 0.0003046687570645472 -0.024661115370743714" rpy="1.50192092503764 -0.10834356458816563 0.0060968888999008986"/>
         <geometry>
            <mesh filename="file://converted_palm.stl"/>
         </geometry>
         <material name="white"/>
      </visual>
   </link>
   <joint type="fixed" name="wrist_roll_link2hand_palm_link_fixed">
      <parent link="wrist_roll_link"/>
      <child link="hand_palm_link"/>
      <origin xyz="0.012 0.0 0.1405" rpy="0.0 0.0 3.141592653589793"/>
   </joint>
   <link name="hand_motor_dummy_link">
      <inertial>
         <origin xyz="0.0 0.0 0.0" rpy="0.0 0.0 0.0"/>
         <mass value="0.001"/>
         <inertia ixx="0.001" iyy="0.001" izz="0.001" ixy="0" ixz="0" iyz="0"/>
      </inertial>
   </link>
   <link name="hand_motor_joint_jointbody">
      <inertial>
         <origin xyz="0.0 0.0 0.0" rpy="0.0 0.0 0.0"/>
         <mass value="0.001"/>
         <inertia ixx="1e-09" iyy="1e-09" izz="1e-09" ixy="0" ixz="0" iyz="0"/>
      </inertial>
   </link>
   <joint type="fixed" name="hand_motor_joint">
      <parent link="hand_palm_link"/>
      <child link="hand_motor_joint_jointbody"/>
      <origin xyz="0.0 0.0 0.0" rpy="0.0 0.0 0.0"/>
      <axis xyz="1.0 0.0 0.0"/>
      <limit lower="-0.798" upper="1.24" effort="100" velocity="100"/>
   </joint>
   <joint type="fixed" name="hand_motor_joint_offset">
      <parent link="hand_motor_joint_jointbody"/>
      <child link="hand_motor_dummy_link"/>
      <origin xyz="-0.0 -0.0 -0.0" rpy="0.0 0.0 0.0"/>
   </joint>
   <link name="hand_l_proximal_link">
      <inertial>
         <origin xyz="0.0 0.0 0.0" rpy="0.0 0.0 0.0"/>
         <mass value="0.001"/>
         <inertia ixx="0.001" iyy="0.001" izz="0.001" ixy="0" ixz="0" iyz="0"/>
      </inertial>
   </link>
   <link name="hand_l_proximal_joint_jointbody">
      <inertial>
         <origin xyz="0.0 0.0 0.0" rpy="0.0 0.0 0.0"/>
         <mass value="0.001"/>
         <inertia ixx="1e-09" iyy="1e-09" izz="1e-09" ixy="0" ixz="0" iyz="0"/>
      </inertial>
   </link>
   <joint type="fixed" name="hand_l_proximal_joint">
      <parent link="hand_palm_link"/>
      <child link="hand_l_proximal_joint_jointbody"/>
      <origin xyz="-0.01675 -0.0245 -0.0175" rpy="0.0 0.0 0.0"/>
      <axis xyz="1.0 0.0 0.0"/>
      <limit lower="-0.798" upper="1.24" effort="100" velocity="100"/>
   </joint>
   <joint type="fixed" name="hand_l_proximal_joint_offset">
      <parent link="hand_l_proximal_joint_jointbody"/>
      <child link="hand_l_proximal_link"/>
      <origin xyz="-0.0 -0.0 -0.0" rpy="0.0 0.0 0.0"/>
   </joint>
   <link name="hand_l_spring_proximal_link">
      <inertial>
         <origin xyz="0.021418 0.00248 0.022688" rpy="0.0 0.0 0.0"/>
         <mass value="0.001"/>
         <inertia ixx="0.001" iyy="0.001" izz="0.001" ixy="0" ixz="0" iyz="0"/>
      </inertial>
      <visual name="l_proximal">
         <origin xyz="0.018756786737817114 -0.0022016807988067587 0.030663586197124566" rpy="-0.03933602449065021 0.008780635779167989 1.5820618628235594"/>
         <geometry>
            <mesh filename="file://converted_l_proximal.stl"/>
         </geometry>
         <material name="white"/>
      </visual>
   </link>
   <joint type="fixed" name="hand_l_proximal_link2hand_l_spring_proximal_link_fixed">
      <parent link="hand_l_proximal_link"/>
      <child link="hand_l_spring_proximal_link"/>
      <origin xyz="0.0 0.0 0.0" rpy="0.0 0.0 0.0"/>
   </joint>
   <link name="hand_l_mimic_distal_link">
      <inertial>
         <origin xyz="0.0 0.0 0.0" rpy="0.0 0.0 0.0"/>
         <mass value="0.001"/>
         <inertia ixx="0.001" iyy="0.001" izz="0.001" ixy="0" ixz="0" iyz="0"/>
      </inertial>
   </link>
   <joint type="fixed" name="hand_l_spring_proximal_link2hand_l_mimic_distal_link_fixed">
      <parent link="hand_l_spring_proximal_link"/>
      <child link="hand_l_mimic_distal_link"/>
      <origin xyz="0.0 0.0 0.07" rpy="0.0 0.0 0.0"/>
   </joint>
   <link name="hand_l_distal_link">
      <inertial>
         <origin xyz="0.011116 0.005679 0.017532" rpy="0.0 0.0 0.0"/>
         <mass value="0.001"/>
         <inertia ixx="0.0" iyy="0.0" izz="0.0" ixy="0" ixz="0" iyz="0"/>
      </inertial>
      <visual name="l_distal">
         <origin xyz="0.015250045343675871 0.004431677463853842 0.01933372017980011" rpy="-0.5863904637985864 0.20040906183306828 1.8693945207712246"/>
         <geometry>
            <mesh filename="file://converted_l_distal.stl"/>
         </geometry>
         <material name="white"/>
      </visual>
   </link>
   <joint type="fixed" name="hand_l_mimic_distal_link2hand_l_distal_link_fixed">
      <parent link="hand_l_mimic_distal_link"/>
      <child link="hand_l_distal_link"/>
      <origin xyz="0.0 0.0 0.0" rpy="0.0 0.0 0.0"/>
   </joint>
   <link name="hand_l_finger_tip_frame">
      <inertial>
         <origin xyz="0.0 0.0 0.0" rpy="0.0 0.0 0.0"/>
         <mass value="0.001"/>
         <inertia ixx="0.001" iyy="0.001" izz="0.001" ixy="0" ixz="0" iyz="0"/>
      </inertial>
   </link>
   <joint type="fixed" name="hand_l_distal_link2hand_l_finger_tip_frame_fixed">
      <parent link="hand_l_distal_link"/>
      <child link="hand_l_finger_tip_frame"/>
      <origin xyz="0.01675 0.01865 0.04289" rpy="-1.5707963267948957 0.0 0.0"/>
   </joint>
   <link name="hand_l_finger_vacuum_frame">
      <inertial>
         <origin xyz="0.0 0.0 0.0" rpy="0.0 0.0 0.0"/>
         <mass value="0.001"/>
         <inertia ixx="0.001" iyy="0.001" izz="0.001" ixy="0" ixz="0" iyz="0"/>
      </inertial>
   </link>
   <joint type="fixed" name="hand_l_distal_link2hand_l_finger_vacuum_frame_fixed">
      <parent link="hand_l_distal_link"/>
      <child link="hand_l_finger_vacuum_frame"/>
      <origin xyz="0.00475 -0.011539 0.03322" rpy="0.7853970066908718 0.0 0.0"/>
   </joint>
   <link name="hand_r_proximal_link">
      <inertial>
         <origin xyz="0.0 0.0 0.0" rpy="0.0 0.0 0.0"/>
         <mass value="0.001"/>
         <inertia ixx="0.001" iyy="0.001" izz="0.001" ixy="0" ixz="0" iyz="0"/>
      </inertial>
   </link>
   <link name="hand_r_proximal_joint_jointbody">
      <inertial>
         <origin xyz="0.0 0.0 0.0" rpy="0.0 0.0 0.0"/>
         <mass value="0.001"/>
         <inertia ixx="1e-09" iyy="1e-09" izz="1e-09" ixy="0" ixz="0" iyz="0"/>
      </inertial>
   </link>
   <joint type="fixed" name="hand_r_proximal_joint">
      <parent link="hand_palm_link"/>
      <child link="hand_r_proximal_joint_jointbody"/>
      <origin xyz="-0.01675 0.0245 -0.0175" rpy="0.0 0.0 0.0"/>
      <axis xyz="-1.0 0.0 0.0"/>
      <limit lower="-0.798" upper="1.24" effort="100" velocity="100"/>
   </joint>
   <joint type="fixed" name="hand_r_proximal_joint_offset">
      <parent link="hand_r_proximal_joint_jointbody"/>
      <child link="hand_r_proximal_link"/>
      <origin xyz="-0.0 -0.0 -0.0" rpy="0.0 0.0 0.0"/>
   </joint>
   <link name="hand_r_spring_proximal_link">
      <inertial>
         <origin xyz="0.013203 0.002096 0.023311" rpy="0.0 0.0 0.0"/>
         <mass value="0.001"/>
         <inertia ixx="0.001" iyy="0.001" izz="0.001" ixy="0" ixz="0" iyz="0"/>
      </inertial>
      <visual name="r_proximal">
         <origin xyz="0.018127675618202742 0.002165994135696481 0.03085762100817255" rpy="-0.017569303178356477 -0.0058296485513933405 1.6243022838688717"/>
         <geometry>
            <mesh filename="file://converted_r_proximal.stl"/>
         </geometry>
         <material name="white"/>
      </visual>
   </link>
   <joint type="fixed" name="hand_r_proximal_link2hand_r_spring_proximal_link_fixed">
      <parent link="hand_r_proximal_link"/>
      <child link="hand_r_spring_proximal_link"/>
      <origin xyz="0.0 0.0 0.0" rpy="0.0 0.0 0.0"/>
   </joint>
   <link name="hand_r_mimic_distal_link">
      <inertial>
         <origin xyz="0.0 0.0 0.0" rpy="0.0 0.0 0.0"/>
         <mass value="0.001"/>
         <inertia ixx="0.001" iyy="0.001" izz="0.001" ixy="0" ixz="0" iyz="0"/>
      </inertial>
   </link>
   <joint type="fixed" name="hand_r_spring_proximal_link2hand_r_mimic_distal_link_fixed">
      <parent link="hand_r_spring_proximal_link"/>
      <child link="hand_r_mimic_distal_link"/>
      <origin xyz="0.0 0.0 0.07" rpy="0.0 0.0 0.0"/>
   </joint>
   <link name="hand_r_distal_link">
      <inertial>
         <origin xyz="0.014256 -0.008321 0.015591" rpy="0.0 0.0 0.0"/>
         <mass value="0.001"/>
         <inertia ixx="0.001" iyy="0.001" izz="0.001" ixy="0" ixz="0" iyz="0"/>
      </inertial>
      <visual name="r_distal">
         <origin xyz="0.017135123870572425 -0.0076525979236625385 0.017139450034662683" rpy="-0.23310539183297097 -0.3393364893998281 1.585096294124026"/>
         <geometry>
            <mesh filename="file://converted_r_distal.stl"/>
         </geometry>
         <material name="white"/>
      </visual>
   </link>
   <joint type="fixed" name="hand_r_mimic_distal_link2hand_r_distal_link_fixed">
      <parent link="hand_r_mimic_distal_link"/>
      <child link="hand_r_distal_link"/>
      <origin xyz="0.0 0.0 0.0" rpy="0.0 0.0 0.0"/>
   </joint>
   <link name="hand_r_finger_tip_frame">
      <inertial>
         <origin xyz="0.0 0.0 0.0" rpy="0.0 0.0 0.0"/>
         <mass value="0.001"/>
         <inertia ixx="0.001" iyy="0.001" izz="0.001" ixy="0" ixz="0" iyz="0"/>
      </inertial>
   </link>
   <joint type="fixed" name="hand_r_distal_link2hand_r_finger_tip_frame_fixed">
      <parent link="hand_r_distal_link"/>
      <child link="hand_r_finger_tip_frame"/>
      <origin xyz="0.01675 -0.01865 0.04289" rpy="1.5707963267948963 0.0 0.0"/>
   </joint>
   <link name="hand_camera_frame">
      <inertial>
         <origin xyz="0.0 0.0 0.0" rpy="0.0 0.0 0.0"/>
         <mass value="0.01"/>
         <inertia ixx="0.001" iyy="0.001" izz="0.001" ixy="0" ixz="0" iyz="0"/>
      </inertial>
   </link>
   <joint type="fixed" name="hand_palm_link2hand_camera_frame_fixed">
      <parent link="hand_palm_link"/>
      <child link="hand_camera_frame"/>
      <origin xyz="0.039 0.0 -0.0045" rpy="0.0 0.0 0.0"/>
   </joint>
   <link name="hand_camera_gazebo_frame">
      <inertial>
         <origin xyz="0.0 0.0 0.0" rpy="0.0 0.0 0.0"/>
         <mass value="0.01"/>
         <inertia ixx="0.001" iyy="0.001" izz="0.001" ixy="0" ixz="0" iyz="0"/>
      </inertial>
   </link>
   <joint type="fixed" name="hand_camera_frame2hand_camera_gazebo_frame_fixed">
      <parent link="hand_camera_frame"/>
      <child link="hand_camera_gazebo_frame"/>
      <origin xyz="0.0 0.0 0.0" rpy="1.5707963267948966 -1.5707963267948966 0.0"/>
   </joint>
   <material name="white">
      <color rgba="1 1 1 1"/>
   </material>
</robot>
