<mujoco model="cabinet">
  <body pos="0.0 0.0 0.0">
    <geom type="box" size="0.1 0.15 0.005" pos="0.0 0.0 0.005" rgba="0.1 0.5 0.1 1.0"/>
    <geom type="box" size="0.1 0.005 0.08" pos="0.0 0.155 0.08" rgba="0.1 0.5 0.1 1.0"/>
    <geom type="box" size="0.1 0.005 0.08" pos="0.0 -0.155 0.08" rgba="0.1 0.5 0.1 1.0"/>
    <geom type="box" size="0.005 0.15 0.08" pos="0.095 0.0 0.08" rgba="0.1 0.5 0.1 1.0"/>
    <geom type="box" size="0.005 0.075 0.075" pos="-0.085 0.075 0.085" rgba="0.9 0.6 0.1 1.0"/>
    <body pos="-0.095 0.0 0.0">
      <joint name="slide" type="slide" axis="0 1 0" range="0.0 0.15" armature="1e-5"/>
      <geom type="box" size="0.005 0.075 0.075" pos="0.0 -0.075 0.085" rgba="0.9 0.3 0.7 1.0"/>
      <geom type="box" size="0.01 0.003 0.03" pos="-0.01 -0.135 0.085" rgba="0.6 0.0 0.4 1.0"/>
    </body>
  </body>
  <body pos="0.0 0.0 0.16">
    <geom type="box" size="0.095 0.15 0.005" pos="0.0 0.0 0.005" rgba="0.3 0.3 0.3 1.0"/>
    <geom type="box" size="0.1 0.005 0.06" pos="0.0 0.155 0.06" rgba="0.1 0.5 0.1 1.0"/>
    <geom type="box" size="0.1 0.005 0.06" pos="0.0 -0.155 0.06" rgba="0.1 0.5 0.1 1.0"/>
    <geom type="box" size="0.005 0.15 0.06" pos="0.095 0.0 0.06" rgba="0.1 0.5 0.1 1.0"/>
    <geom type="box" size="0.005 0.15 0.04" pos="-0.095 0.0 0.04" rgba="0.1 0.8 0.8 1.0"/>
    <geom type="box" size="0.005 0.05 0.02" pos="-0.095 0.1 0.10" rgba="0.1 0.8 0.8 1.0"/>
    <geom type="box" size="0.005 0.05 0.02" pos="-0.095 -0.1 0.10" rgba="0.1 0.8 0.8 1.0"/>
    <body pos="0.095 0.0 0.12">
      <joint name="hinge" axis="0 1 0" range="0.0 3.1415"/>
      <geom type="box" size="0.1 0.16 0.005" pos="-0.095 0.0 0.005" rgba="0.8 0.8 0.1 1.0"/>
    </body>
  </body>
</mujoco>
