<mujoco model="hsr_body">
  <body name="hsr_body">
    <body name="base_link">
      <inertial pos="-0.025978 -0.005498 0.17633" quat="0.995796 0.0411155 -0.0685908 0.0446655" mass="50" diaginertia="0.378627 0.344913 0.145159" />
      <geom type="mesh" mesh="base" material="hsr_white" />
      <body name="base_range_sensor_link" pos="0.1675 0 0.1844">
        <inertial pos="0 0 0" mass="0.01" diaginertia="0.001 0.001 0.001" />
        <geom type="mesh" mesh="laser" material="hsr_black" />
      </body>
      <body name="base_imu_frame" pos="0.0005 0.1296 0.181">
        <inertial pos="0 0 0" mass="0.01" diaginertia="0.001 0.001 0.001" />
      </body>
      <body name="base_f_bumper_link">
        <inertial pos="0 0 0" quat="0.5 0.5 -0.5 0.5" mass="0.06" diaginertia="0.001875 0.001437 0.001437" />
        <!-- <joint name="base_f_bumper_joint" pos="0 0 0" axis="1 0 0" /> -->
        <geom type="mesh" mesh="bumper" material="hsr_black" />
      </body>
      <body name="base_b_bumper_link" pos="0 0.0013 0" quat="0 0 0 1">
        <inertial pos="0 0 0" quat="0.5 0.5 -0.5 0.5" mass="0.06" diaginertia="0.001875 0.001437 0.001437" />
        <!-- <joint name="base_b_bumper_joint" pos="0 0 0" axis="1 0 0" /> -->
        <geom type="mesh" mesh="bumper" material="hsr_black" />
      </body>
      <body name="torso_lift_link" pos="0 0 0.752">
        <inertial pos="-0.051142 0.003454 -0.2905" quat="0.511154 0.00760492 -0.0140194 0.859341" mass="3.42078" diaginertia="0.105342 0.104252 0.0127461" />
        <!-- TODO: Disable torso_lift_joint because mimic joint is not supported in the pinocchio library. This will be resolved when you can install pinocchio version 3.5.0 with pip. -->
        <!-- <joint name="torso_lift_joint" pos="0 0 0" axis="0 0 1" type="slide" range="0 0.345" actuatorfrcrange="-300 300" damping="500" /> -->
        <geom type="mesh" mesh="torso" material="hsr_black" pos="1e-3 0 0" />
        <body name="head_pan_link">
          <inertial pos="0.001724 -0.001969 -0.028886" quat="0.865343 0.459592 0.192259 -0.0547077" mass="0.571903" diaginertia="0.00102408 0.00077623 0.000589392" />
          <!-- <joint name="head_pan_joint" pos="0 0 0" axis="0 0 1" range="-3.84 1.75" actuatorfrcrange="-100 100" damping="1" /> -->
          <geom type="mesh" mesh="head_pan" material="hsr_white" />
          <body name="head_tilt_link" pos="0.02 0 0">
            <inertial pos="-0.055376 -0.002436 0.117733" quat="0.973833 0.0131235 -0.226864 -0.00327368" mass="2.1238" diaginertia="0.0218915 0.0149823 0.0091862" />
            <!-- <joint name="head_tilt_joint" pos="0 0 0" axis="0 -1 0" range="-1.57 0.52" actuatorfrcrange="-100 100" damping="10" /> -->
            <geom type="mesh" mesh="head" material="hsr_white" />
            <geom type="mesh" mesh="tablet" material="hsr_black" pos="1e-3 0 0" />
            <body name="head_l_stereo_camera_link" pos="0.02 0.07 0.061" quat="0.5 -0.5 0.5 -0.5">
              <inertial pos="0 0 0" mass="0.01" diaginertia="0.001 0.001 0.001" />
              <body name="head_l_stereo_camera_gazebo_frame" quat="0.5 0.5 -0.5 0.5">
                <inertial pos="0 0 0" mass="0.01" diaginertia="0.001 0.001 0.001" />
              </body>
            </body>
            <body name="head_r_stereo_camera_link" pos="0.02 -0.07 0.061" quat="0.5 -0.5 0.5 -0.5">
              <inertial pos="0 0 0" mass="0.01" diaginertia="0.001 0.001 0.001" />
              <body name="head_r_stereo_camera_gazebo_frame" quat="0.5 0.5 -0.5 0.5">
                <inertial pos="0 0 0" mass="0.01" diaginertia="0.001 0.001 0.001" />
              </body>
            </body>
            <body name="head_center_camera_frame" pos="0.0195 0 0.061" quat="0.5 -0.5 0.5 -0.5">
              <camera name="head" fovy="62" pos="0 0 0" euler="2.35619 0 0"/>
              <inertial pos="0 0 0" mass="0.01" diaginertia="0.001 0.001 0.001" />
              <body name="head_center_camera_gazebo_frame" quat="0.5 0.5 -0.5 0.5">
                <inertial pos="0 0 0" mass="0.01" diaginertia="0.001 0.001 0.001" />
              </body>
            </body>
            <body name="head_rgbd_sensor_link" pos="-0.079796 0.022 0.215172" quat="0.5 -0.5 0.5 -0.5">
              <inertial pos="0 0 0" mass="0.01" diaginertia="0.001 0.001 0.001" />
              <geom type="mesh" mesh="xtion" material="hsr_black" />
              <body name="head_rgbd_sensor_gazebo_frame" quat="0.5 0.5 -0.5 0.5">
                <inertial pos="0 0 0" mass="0.01" diaginertia="0.001 0.001 0.001" />
              </body>
            </body>
          </body>
        </body>
      </body>
      <body name="arm_lift_link" pos="0 0 0.34">
        <inertial pos="0.051549 0.042438 -0.064145" quat="-0.111496 0.499152 -0.110462 0.852182" mass="1.27582" diaginertia="0.00909548 0.00799354 0.00328099" />
        <joint name="arm_lift_joint" pos="0 0 0" axis="0 0 1" type="slide" range="0 0.69" actuatorfrcrange="-300 300" damping="1" />
        <geom type="mesh" mesh="shoulder" material="hsr_white" />
        <body name="arm_flex_link" pos="0.141 0.078 0">
          <inertial pos="0.000632 0.006404 0.118529" quat="0.99969 -0.008317 0.0017536 -0.0233824" mass="1.33929" diaginertia="0.00752902 0.00710259 0.00155039" />
          <joint name="arm_flex_joint" pos="0 0 0" axis="0 -1 0" range="-2.62 0" actuatorfrcrange="-100 100" damping="1" />
          <geom type="mesh" mesh="arm_flex" material="hsr_white" />
          <body name="arm_roll_link" pos="0.005 0 0.345">
            <inertial pos="-0.006927 0.002039 -0.064837" quat="0.704471 0.707171 -0.0444888 0.0406182" mass="0.247936" diaginertia="0.00426928 0.00411787 0.00078077" />
            <joint name="arm_roll_joint" pos="0 0 0" axis="0 0 1" range="-2.09 3.84" actuatorfrcrange="-100 100" damping="0.1" />
            <geom type="mesh" mesh="arm_roll" material="hsr_white" />
            <body name="wrist_flex_link">
              <inertial pos="0.000131 -0.003929 0.00217" quat="0.672298 0.740248 0.0055614 0.00418043" mass="0.681225" diaginertia="7.43604e-05 6.49274e-05 3.81796e-05" />
              <joint name="wrist_flex_joint" pos="0 0 0" axis="0 -1 0" range="-1.92 1.22" actuatorfrcrange="-100 100" damping="1" />
              <geom size="0.017 0.02" pos="0 0 0.03" type="cylinder" rgba="0.33 0.33 0.33 1" material="hsr_black" />
              <body name="wrist_ft_sensor_mount_link">
                <inertial pos="0 0 0" mass="0.01" diaginertia="0.001 0.001 0.001" />
                <joint name="wrist_roll_joint" pos="0 0 0" axis="0 0 1" range="-1.92 3.67" actuatorfrcrange="-100 100" damping="1" />
                <body name="wrist_ft_sensor_frame" pos="0 0 0.0735" quat="0 1 0 0">
                  <inertial pos="0 0 0" mass="0.01" diaginertia="0.001 0.001 0.001" />
                  <!-- <joint name="wrist_ft_sensor_frame_joint" pos="0 0 0" axis="1 0 0" actuatorfrcrange="-100 100" /> -->
                  <site name="force_sensor" pos="0 0 0"
                        type="box" size="0.005 0.005 0.01" rgba="0.6 0.1 0.1 1" group="2"/>
                  <body name="wrist_roll_link" pos="0 0 0.0735" quat="0 -1 0 0">
                    <inertial pos="-0.001416 -0.001547 0.081689" quat="0.988073 0.0424396 -0.0351605 -0.143785" mass="0.761692" diaginertia="0.000811657 0.000766039 0.000449422" />
                    <geom type="mesh" mesh="wrist_roll" material="hsr_white" />
                    <body name="hand_palm_link" pos="0.012 0 0.1405" quat="0 0 0 1">
                      <inertial pos="0 0 0" mass="0.15" diaginertia="0.015 0.015 0.015" />
                      <geom type="mesh" mesh="palm" material="hsr_white" />
                      <body name="hand_motor_dummy_link">
                        <inertial pos="0 0 0" mass="0.001" diaginertia="0.001 0.001 0.001" />
                        <joint name="hand_motor_joint" pos="0 0 0" axis="1 0 0" range="-0.798 1.24" actuatorfrcrange="-100 100" damping="0.0001" />
                      </body>
                      <body name="hand_l_proximal_link" pos="-0.01675 -0.0245 -0.0175">
                        <inertial pos="0 0 0" mass="0.001" diaginertia="0.001 0.001 0.001" />
                        <joint name="hand_l_proximal_joint" pos="0 0 0" axis="1 0 0" range="-0.798 1.24" actuatorfrcrange="-100 100" damping="0.0001" />
                        <body name="hand_l_spring_proximal_link">
                          <inertial pos="0.021418 0.00248 0.022688" mass="0.001" diaginertia="0.001 0.001 0.001" />
                          <!-- <joint name="hand_l_spring_proximal_joint" pos="0 0 0" axis="1 0 0" range="0 0.698" actuatorfrcrange="-10 10" damping="0.0001" /> -->
                          <geom type="mesh" mesh="l_proximal" material="hsr_black" />
                          <body name="hand_l_mimic_distal_link" pos="0 0 0.07">
                            <inertial pos="0 0 0" mass="0.001" diaginertia="0.001 0.001 0.001" />
                            <!-- <joint name="hand_l_mimic_distal_joint" pos="0 0 0" axis="1 0 0" range="-0.698 0" actuatorfrcrange="-100 100" damping="0.0001" /> -->
                            <body name="hand_l_distal_link">
                              <inertial pos="0.011116 0.005679 0.017532" mass="0.001" diaginertia="0 0 0" />
                              <!-- <joint name="hand_l_distal_joint" pos="0 0 0" axis="1 0 0" range="-1.24 0.798" actuatorfrcrange="-100 100" damping="0.0001" /> -->
                              <geom type="mesh" mesh="l_distal" material="hsr_black" />
                              <body name="hand_l_finger_tip_frame" pos="0.01675 0.01865 0.04289" quat="0.707107 -0.707107 0 0">
                                <inertial pos="0 0 0" mass="0.001" diaginertia="0.001 0.001 0.001" />
                              </body>
                              <body name="hand_l_finger_vacuum_frame" pos="0.00475 -0.011539 0.03322" quat="0.92388 0.382683 0 0">
                                <inertial pos="0 0 0" mass="0.001" diaginertia="0.001 0.001 0.001" />
                              </body>
                            </body>
                          </body>
                        </body>
                      </body>
                      <body name="hand_r_proximal_link" pos="-0.01675 0.0245 -0.0175">
                        <inertial pos="0 0 0" mass="0.001" diaginertia="0.001 0.001 0.001" />
                        <joint name="hand_r_proximal_joint" pos="0 0 0" axis="-1 0 0" range="-0.798 1.24" actuatorfrcrange="-100 100" damping="0.0001" />
                        <body name="hand_r_spring_proximal_link">
                          <inertial pos="0.013203 0.002096 0.023311" mass="0.001" diaginertia="0.001 0.001 0.001" />
                          <!-- <joint name="hand_r_spring_proximal_joint" pos="0 0 0" axis="-1 0 0" range="0 0.698" actuatorfrcrange="-10 10" damping="0.0001" /> -->
                          <geom type="mesh" mesh="r_proximal" material="hsr_black" />
                          <body name="hand_r_mimic_distal_link" pos="0 0 0.07">
                            <inertial pos="0 0 0" mass="0.001" diaginertia="0.001 0.001 0.001" />
                            <!-- <joint name="hand_r_mimic_distal_joint" pos="0 0 0" axis="-1 0 0" range="-0.698 0" actuatorfrcrange="-100 100" damping="0.0001" /> -->
                            <body name="hand_r_distal_link">
                              <inertial pos="0.014256 -0.008321 0.015591" mass="0.001" diaginertia="0.001 0.001 0.001" />
                              <!-- <joint name="hand_r_distal_joint" pos="0 0 0" axis="-1 0 0" range="-1.24 0.798" actuatorfrcrange="-100 100" damping="0.0001" /> -->
                              <geom type="mesh" mesh="r_distal" material="hsr_black" />
                              <body name="hand_r_finger_tip_frame" pos="0.01675 -0.01865 0.04289" quat="0.707107 0.707107 0 0">
                                <inertial pos="0 0 0" mass="0.001" diaginertia="0.001 0.001 0.001" />
                              </body>
                            </body>
                          </body>
                        </body>
                      </body>
                      <body name="hand_camera_frame" pos="0.039 0 -0.0045">
                        <inertial pos="0 0 0" mass="0.01" diaginertia="0.001 0.001 0.001" />
                        <body name="hand_camera_gazebo_frame" quat="0.5 0.5 -0.5 0.5">
                          <inertial pos="0 0 0" mass="0.01" diaginertia="0.001 0.001 0.001" />
                        </body>
                      </body>
                    </body>
                  </body>
                </body>
              </body>
            </body>
          </body>
        </body>
      </body>
    </body>
  </body>
</mujoco>
